Workbook

Sheet Customer_Dim
A1: Customer_ID | B1: Name | C1: Age | D1: Gender | E1: City | F1: State | G1: Country | H1: Loyalty_Level
A2: CUST1000 | B2: sheena bonilla | C2: 55 | D2: Male | E2: Donaldton | F2: North Carolina | G2: USA
A3: CUST1001 | B3: Eugene Nelson | C3: 26 | D3: Female | E3: Phillipsmouth | F3: North Dakota | G3: USA | H3: Platinum
A4: CUST1002 | B4: dr. Benjamin Price | C4: 29 | D4: Female | E4: Kylebury | F4: Alabama | G4: USA | H4: Platinum
A5: CUST1003 | B5: jeremy harris | C5: 59 | D5: Female | E5: Thomastown | F5: Ohio | G5: USA | H5: Bronze
A6: CUST1004 | B6: Caroline Collins | C6: 64 | D6: Female | E6: Nicholasshire | F6: California | G6: USA | H6: Silver
A7: CUST1005 | B7: Christine Vaughn | C7: 24 | D7: Male | E7: East Amandamouth | F7: Oregon | G7: USA | H7: Bronze
A8: CUST1006 | B8: Amber Jackson | C8: 29 | D8: Female | E8: Deborahborough | F8: South Dakota | G8: USA | H8: Platinum
A9: CUST1007 | B9: Daniel Boyd | C9: 29 | D9: Female | E9: West Pamelafurt | F9: West Virginia | G9: USA | H9: Bronze
A10: CUST1008 | B10: Melissa Howard | C10: 53 | D10: Female | E10: Maynardton | F10: New Hampshire | G10: USA | H10: Gold
A11: CUST1009 | B11: Ms. Maria Leach | C11: 64 | D11: Male | E11: Melissashire | F11: Pennsylvania | G11: USA | H11: Platinum
A12: CUST1010 | B12: Dominic Page | C12: 53 | D12: Male | E12: Port Michaelburgh | F12: Pennsylvania | G12: USA | H12: Bronze
A13: CUST1011 | B13: Brian Lopez | C13: 28 | D13: Female | E13: East Krista | F13: New York | G13: USA | H13: Gold
A14: CUST1012 | B14: Kenneth Lambert | C14: 55 | D14: Female | E14: North Kathryn | F14: Kansas | G14: USA | H14: Platinum
... A19: CUST1017 | B19: Adam Cruz | C19: 60 | D19: Female | E19: Brandonville | F19: Georgia | G19: USA | H19: Platinum
A20: CUST1018 | B20: Rhonda Moss | C20: 43 | D20: Male | E20: South William | F20: Kansas | G20: USA
A21: CUST1019 | B21: Michael Torres | C21: 46 | D21: Female | E21: Gonzalezfort | F21: New Jersey | G21: USA | H21: Platinum
A22: CUST1020 | B22: Bridget Allen | C22: 59 | D22: Male | E22: Lake Shaneburgh | F22: Delaware | G22: USA | H22: Silver
A23: CUST1021 | B23: Jeff Martinez | C23: 36 | D23: Female | E23: Smithburgh | F23: Oklahoma | G23: USA | H23: Gold
A24: CUST1022 | B24: paul fox | C24: 33 | D24: Female | E24: Michaelton | F24: Hawaii | G24: USA | H24: Silver
A25: CUST1023 | B25: Jonathan Steele | C25: 52 | D25: Female | E25: Molinabury | F25: Oregon | G25: USA | H25: Silver
A26: CUST1024 | B26: Heather Collins | C26: 40 | D26: Male | E26: Rogerschester | F26: Idaho | G26: USA | H26: Platinum
A27: CUST1025 | B27: Diana Taylor | C27: 59 | D27: Female | E27: Vasqueztown | F27: California | G27: USA | H27: Bronze
A28: CUST1026 | B28: Amber Carlson | C28: 18 | D28: Female | E28: East Michellemouth | F28: Missouri | G28: USA | H28: Gold
A29: CUST1027 | B29: Leslie Johnson | C29: 31 | D29: Male | E29: Mollyshire | F29: Utah | G29: USA
A30: CUST1028 | B30: Joshua Ryan | C30: 27 | D30: Female | E30: New David | F30: New Jersey | G30: USA | H30: Platinum
A31: CUST1029 | B31: David Arnold | C31: 54 | D31: Female | E31: East Jennifer | F31: California | G31: USA | H31: Silver
A32: CUST1030 | B32: Jessica Acevedo | C32: 64 | D32: Female | E32: Amybury | F32: Pennsylvania | G32: USA | H32: Bronze
A33: CUST1031 | B33: Sarah Vance | C33: 41 | D33: Male | E33: Johnsonville | F33: Oregon | G33: USA | H33: Silver
A34: CUST1032 | B34: Mike Jennings | C34: 48 | D34: Female | E34: Fostermouth | F34: Arizona | G34: USA | H34: Gold
A35: CUST1033 | B35: Robert Jones DDS | C35: 25 | D35: Male | E35: Tristanton | F35: Oklahoma | G35: USA | H35: Platinum
A36: CUST1034 | B36: Christopher Olson | C36: 27 | D36: Female | E36: West Richard | F36: Maryland | G36: USA | H36: Platinum
A37: CUST1035 | B37: Rachel Myers | C37: 52 | D37: Male | E37: Robertberg | F37: North Dakota | G37: USA | H37: Silver
A38: CUST1036 | B38: Thomas Phillips | C38: 20 | D38: Female | E38: Luisfurt | F38: Georgia | G38: USA | H38: Gold
A39: CUST1037 | B39: Christopher Carter | C39: 27 | D39: Female | E39: Brendastad | F39: South Dakota | G39: USA
A40: CUST1038 | B40: Deanna Simpson | C40: 35 | D40: Female | E40: Brownport | F40: North Dakota | G40: USA | H40: Bronze
A41: CUST1039 | B41: Tonya Reynolds | C41: 55 | D41: Female | E41: Darleneton | F41: Michigan | G41: USA | H41: Gold
A42: CUST1040 | B42: Eric Vega | C42: 50 | D42: Male | E42: Williamsonland | F42: Kansas | G42: USA | H42: Gold
A43: CUST1041 | B43: James Gibbs | C43: 21 | D43: Male | E43: Mooneyshire | F43: Alaska | G43: USA | H43: Platinum
A44: CUST1042 | B44: William Martin | C44: 19 | D44: Male | E44: Ryanburgh | F44: Connecticut | G44: USA | H44: Platinum
...

Sheet Product_Dim
A1: Product_ID | B1: Product_Name | C1: Category | D1: Sub_Category | E1: Brand | F1: Cost | G1: Stock
A2: PROD0 | B2: Brother Laser Printer | C2: Electronics | D2: Computer | E2: Hunt Inc | F2: 112.42 | G2: 416
A3: PROD1 | B3: Men's Graphic T-Shirt | C3: Clothing | D3: Tops | E3: Terry-Moore | F3: 342.56 | G3: 181
A4: PROD2 | B4: Women's Casual Hoodie | C4: Clothing | D4: Outerwear | E4: Sims Inc | F4: 0 | G4: 352
A5: PROD3 | B5: Men's Running Jacket | C5: Clothing | D5: Outerwear | E5: Pineda Ltd | F5: 364.67 | G5: 452
A6: PROD4 | B6: Women's Yoga Pants | C6: Clothing | D6: Bottoms | E6: Gonzales-Davis | F6: 306.46 | G6: 487
A7: PROD5 | B7: Men's Leather Belt | C7: Clothing | D7: Accessories | E7: Baldwin, Garza and Gonzalez | F7: 261 | G7: 59
A8: PROD6 | B8: Herbal Face Moisturizer | C8: Beauty | D8: Skincare | E8: Davidson PLC | F8: 312.8 | G8: 350
A9: PROD7 | B9: LED Table Lamp | C9: Home | D9: Lighting | E9: Harrell LLC | F9: 218.86 | G9: 170
A10: PROD8 | B10: Wireless Bluetooth Earbuds | C10: Electronics | D10: Audio | E10: Perez-Johnston | F10: 439.07 | G10: 142
A11: PROD9 | B11: Adjustable Dumbbell Set | C11: Sports | D11: Fitness | E11: Hill PLC | F11: 495.72 | G11: 323
A12: PROD10 | B12: Ceramic Kitchen Bowl Set | C12: Home | D12: Kitchen | E12: Hamilton Group | F12: 298.86 | G12: 308
A13: PROD11 | B13: HD Smart TV Stick | C13: Electronics | D13: Accessories | E13: Gibson, Hobbs and Weaver | F13: 449.4 | G13: 0
... A101: PROD99 | B101: Stainless Steel Cookware Set | C101: Home | D101: Kitchen | E101: Campbell Ltd | F101: 201.41 | G101: 146

Sheet Store_Dim
A1: Store_ID | B1: Store_Name | C1: Region | D1: City | E1: Store_Type
A2: STORE0 | B2: Rivera-Warner | C2: East | D2: Washingtonfurt | E2: Flagship
A3: STORE1 | B3: Martinez, Adkins and Johnson | C3: North | D3: Danielmouth | E3: Flagship
A4: STORE2 | B4: Black-Horn | C4: South | D4: North Nancyview | E4: Outlet
A5: STORE3 | B5: Johnson-Wright | C5: North | D5: Hoodberg | E5: Outlet
A6: STORE4 | B6: Alexander Group | C6: South | D6: Port Sharon | E6: Online
A7: STORE5 | B7: Gray Ltd | C7: North | D7: New Michaelchester | E7: Outlet
A8: STORE6 | B8: Benson-Elliott | C8: East | D8: Port Josephberg | E8: Online
A9: STORE7 | B9: Martinez-Mullins | C9: South | D9: Williamsfurt | E9: Online
A10: STORE8 | B10: Bean, Jones and Park | C10: West | D10: Thompsonborough | E10: Online
A11: STORE9 | B11: Moore, Padilla and Butler | C11: South | D11: East Johnstad | E11: Flagship
A12: STORE10 | B12: Hill, Wagner and Ballard | C12: East | D12: East Davidville | E12: Online
... A21: STORE19 | B21: Mann-Austin | C21: East | D21: Vasquezborough | E21: Online

Sheet Sales_Fact
A1: Sales_ID | B1: Order_Date | C1: Customer_ID | D1: Product_ID | E1: Store_ID | F1: Quantity | G1: Unit_Price | H1: Discount | I1: Payment_Type | J1: Total_Amount
A2: SALE0 | B2: 45480 | C2: CUST1409 | D2: PROD97 | E2: STORE3 | F2: 1 | G2: 218.04 | H2: 0.09 | I2: Credit Card | J2: 198.4164
A3: SALE1 | B3: 45285 | C3: CUST1467 | D3: PROD74 | E3: STORE17 | F3: 3 | G3: 104.47 | H3: 0.27 | I3: PayPal | J3: 228.7893
A4: SALE2 | B4: 45446 | C4: CUST1056 | D4: PROD49 | E4: STORE8 | F4: 4 | G4: 914.05 | H4: 0.25 | I4: Credit Card | J4: 2742.15
A5: SALE3 | B5: 45259 | C5: CUST1346 | D5: PROD76 | E5: STORE8 | F5: 1 | G5: 921.51 | H5: 0.16 | I5: COD | J5: 774.0684
A6: SALE4 | B6: 45297 | C6: CUST1493 | D6: PROD59 | E6: STORE5 | F6: 3 | G6: 745.3 | H6: 0.18 | I6: Credit Card | J6: 1833.438
A7: SALE5 | B7: 45499 | C7: CUST1116 | D7: PROD15 | E7: STORE7 | F7: 3 | G7: 147.01 | H7: 0.19 | I7: COD | J7: 357.2343
A8: SALE6 | B8: 45850 | C8: CUST1016 | D8: PROD56 | E8: STORE4 | F8: 2 | G8: 785.31 | H8: 0.15 | I8: PayPal | J8: 1335.027
A9: SALE7 | B9: 45248 | C9: CUST1152 | D9: PROD70 | E9: STORE8 | F9: 4 | G9: 342.39 | H9: 0.23 | I9: PayPal | J9: 1054.5612
A10: SALE8 | B10: 45869 | C10: CUST1464 | D10: PROD33 | E10: STORE0 | F10: 2 | G10: 873.17 | H10: 0.23 | I10: PayPal | J10: 1344.6818
A11: SALE9 | B11: 45335 | C11: CUST1065 | D11: PROD24 | E11: STORE14 | F11: 1 | G11: 278.63 | H11: 0.07 | I11: Credit Card | J11: 259.1259
A12: SALE10 | B12: 45801 | C12: CUST1320 | D12: PROD39 | E12: STORE1 | F12: 4 | G12: 286.92 | H12: 0.17 | I12: Credit Card | J12: 952.5744
A13: SALE11 | B13: 45528 | C13: CUST1237 | D13: PROD88 | E13: STORE4 | F13: 4 | G13: 644.58 | H13: 0.01 | I13: Credit Card | J13: 2552.5368
... A1986: SALE1984 | B1986: 45267 | C1986: CUST1023 | D1986: PROD76 | E1986: STORE19 | F1986: 3 | G1986: 68.45 | H1986: 0.17 | I1986: PayPal | J1986: 170.4405
G1987: =SUM(G2:G1986) -> 1019759.9 | H1987: =SUM(H2:H1986) -> 294.41 | J1987: =SUM(J2:J1986) -> 2155273.7

Sheet Sheet4
A3: Count of Loyalty_Level | B3: Column Labels
A4: Row Labels | B4: Middle-Aged | C4: Senior | D4: Young | E4: Grand Total
A5: Bronze | B5: 56 | C5: 39 | D5: 30 | E5: 125
A6: Female | B6: 25 | C6: 19 | D6: 16 | E6: 60
A7: Male | B7: 31 | C7: 20 | D7: 14 | E7: 65
A8: Gold | B8: 52 | C8: 36 | D8: 34 | E8: 122
A9: Female | B9: 31 | C9: 21 | D9: 16 | E9: 68
A10: Male | B10: 21 | C10: 15 | D10: 18 | E10: 54
A11: Platinum | B11: 59 | C11: 52 | D11: 34 | E11: 145
A12: Female | B12: 32 | C12: 29 | D12: 21 | E12: 82
A13: Male | B13: 27 | C13: 23 | D13: 13 | E13: 63
A14: Silver | B14: 43 | C14: 32 | D14: 29 | E14: 104
A15: Female | B15: 16 | C15: 17 | D15: 18 | E15: 51
A16: Male | B16: 27 | C16: 15 | D16: 11 | E16: 53
A17: Standard | B17: 2 | C17: 1 | D17: 1 | E17: 4
A18: Female | D18: 1 | E18: 1
A19: Male | B19: 2 | C19: 1 | E19: 3
A20: Grand Total | B20: 212 | C20: 160 | D20: 128 | E20: 500

Sheet Sheet6
A3: Sum of Age | B3: Column Labels
A4: Row Labels | B4: Middle-Aged | C4: Senior | D4: Young | E4: Grand Total
A5: Female | B5: 4251 | C5: 5003 | D5: 1712 | E5: 10966
A6: Male | B6: 4284 | C6: 4220 | D6: 1343 | E6: 9847
A7: Grand Total | B7: 8535 | C7: 9223 | D7: 3055 | E7: 20813

Sheet Customer Details
A1: Customer ID | B1: Name | C1: Age | D1: Age Group | E1: Gender | F1: City | G1: State | H1: Country | I1: Loyalty_Level
A2: CUST1000 | B2: =PROPER(Table3[[#This Row],[Name]]) -> Sheena Bonilla | C2: =VLOOKUP(B2,Customer_Dim!B:C,2,0) -> 55 | D2: =IF(C2<30,"Young",IF(C2<=50,"Middle-Aged","Senior")) -> Senior | E2: {=_xlfn.XLOOKUP(A2,Table3[Customer_ID],Table3[[Gender]:[State]])} -> Male | F2: Donaldton | G2: North Carolina | H2: =IF(OR(Customer_Dim!G2="usa",G2="United States of America"),"USA") -> USA | I2: Standard
A3: CUST1001 | B3: =PROPER(Table3[[#This Row],[Name]]) -> Eugene Nelson | C3: =VLOOKUP(B3,Customer_Dim!B:C,2,0) -> 26 | D3: =IF(C3<30,"Young",IF(C3<=50,"Middle-Aged","Senior")) -> Young | E3: {=_xlfn.XLOOKUP(A3,Table3[Customer_ID],Table3[[Gender]:[State]])} -> Female | F3: Phillipsmouth | G3: North Dakota | H3: =IF(OR(Customer_Dim!G3="usa",G3="United States of America"),"USA") -> USA | I3: =VLOOKUP(A3,Customer_Dim!A:H,8,0) -> Platinum
A4: CUST1002 | B4: =PROPER(Table3[[#This Row],[Name]]) -> Dr. Benjamin Price | C4: =VLOOKUP(B4,Customer_Dim!B:C,2,0) -> 29 | D4: =IF(C4<30,"Young",IF(C4<=50,"Middle-Aged","Senior")) -> Young | E4: {=_xlfn.XLOOKUP(A4,Table3[Customer_ID],Table3[[Gender]:[State]])} -> Female | F4: Kylebury | G4: Alabama | H4: =IF(OR(Customer_Dim!G4="usa",G4="United States of America"),"USA") -> USA | I4: =VLOOKUP(A4,Customer_Dim!A:H,8,0) -> Platinum
A5: CUST1003 | B5: =PROPER(Table3[[#This Row],[Name]]) -> Jeremy Harris | C5: =VLOOKUP(B5,Customer_Dim!B:C,2,0) -> 59 | D5: =IF(C5<30,"Young",IF(C5<=50,"Middle-Aged","Senior")) -> Senior | E5: {=_xlfn.XLOOKUP(A5,Table3[Customer_ID],Table3[[Gender]:[State]])} -> Female | F5: Thomastown | G5: Ohio | H5: =IF(OR(Customer_Dim!G5="usa",G5="United States of America"),"USA") -> USA | I5: =VLOOKUP(A5,Customer_Dim!A:H,8,0) -> Bronze
A6: CUST1004 | B6: =PROPER(Table3[[#This Row],[Name]]) -> Caroline Collins | C6: =VLOOKUP(B6,Customer_Dim!B:C,2,0) -> 64 | D6: =IF(C6<30,"Young",IF(C6<=50,"Middle-Aged","Senior")) -> Senior | E6: {=_xlfn.XLOOKUP(A6,Table3[Customer_ID],Table3[[Gender]:[State]])} -> Female | F6: Nicholasshire | G6: California | H6: =IF(OR(Customer_Dim!G6="usa",G6="United States of America"),"USA") -> USA | I6: =VLOOKUP(A6,Customer_Dim!A:H,8,0) -> Silver
A7: CUST1005 | B7: =PROPER(Table3[[#This Row],[Name]]) -> Christine Vaughn | C7: =VLOOKUP(B7,Customer_Dim!B:C,2,0) -> 24 | D7: =IF(C7<30,"Young",IF(C7<=50,"Middle-Aged","Senior")) -> Young | E7: {=_xlfn.XLOOKUP(A7,Table3[Customer_ID],Table3[[Gender]:[State]])} -> Male | F7: East Amandamouth | G7: Oregon | H7: =IF(OR(Customer_Dim!G7="usa",G7="United States of America"),"USA") -> USA | I7: =VLOOKUP(A7,Customer_Dim!A:H,8,0) -> Bronze
A8: CUST1006 | B8: =PROPER(Table3[[#This Row],[Name]]) -> Amber Jackson | C8: =VLOOKUP(B8,Customer_Dim!B:C,2,0) -> 29 | D8: =IF(C8<30,"Young",IF(C8<=50,"Middle-Aged","Senior")) -> Young | E8: {=_xlfn.XLOOKUP(A8,Table3[Customer_ID],Table3[[Gender]:[State]])} -> Female | F8: Deborahborough | G8: South Dakota | H8: =IF(OR(Customer_Dim!G8="usa",G8="United States of America"),"USA") -> USA | I8: =VLOOKUP(A8,Customer_Dim!A:H,8,0) -> Platinum
A9: CUST1007 | B9: =PROPER(Table3[[#This Row],[Name]]) -> Daniel Boyd | C9: =VLOOKUP(B9,Customer_Dim!B:C,2,0) -> 29 | D9: =IF(C9<30,"Young",IF(C9<=50,"Middle-Aged","Senior")) -> Young | E9: {=_xlfn.XLOOKUP(A9,Table3[Customer_ID],Table3[[Gender]:[State]])} -> Female | F9: West Pamelafurt | G9: West Virginia | H9: =IF(OR(Customer_Dim!G9="usa",G9="United States of America"),"USA") -> USA | I9: =VLOOKUP(A9,Customer_Dim!A:H,8,0) -> Bronze
A10: CUST1008 | B10: =PROPER(Table3[[#This Row],[Name]]) -> Melissa Howard | C10: =VLOOKUP(B10,Customer_Dim!B:C,2,0) -> 53 | D10: =IF(C10<30,"Young",IF(C10<=50,"Middle-Aged","Senior")) -> Senior | E10: {=_xlfn.XLOOKUP(A10,Table3[Customer_ID],Table3[[Gender]:[State]])} -> Female | F10: Maynardton | G10: New Hampshire | H10: =IF(OR(Customer_Dim!G10="usa",G10="United States of America"),"USA") -> USA | I10: =VLOOKUP(A10,Customer_Dim!A:H,8,0) -> Gold
A11: CUST1009 | B11: =PROPER(Table3[[#This Row],[Name]]) -> Ms. Maria Leach | C11: =VLOOKUP(B11,Customer_Dim!B:C,2,0) -> 64 | D11: =IF(C11<30,"Young",IF(C11<=50,"Middle-Aged","Senior")) -> Senior | E11: {=_xlfn.XLOOKUP(A11,Table3[Customer_ID],Table3[[Gender]:[State]])} -> Male | F11: Melissashire | G11: Pennsylvania | H11: =IF(OR(Customer_Dim!G11="usa",G11="United States of America"),"USA") -> USA | I11: =VLOOKUP(A11,Customer_Dim!A:H,8,0) -> Platinum
A12: CUST1010 | B12: =PROPER(Table3[[#This Row],[Name]]) -> Dominic Page | C12: =VLOOKUP(B12,Customer_Dim!B:C,2,0) -> 53 | D12: =IF(C12<30,"Young",IF(C12<=50,"Middle-Aged","Senior")) -> Senior | E12: {=_xlfn.XLOOKUP(A12,Table3[Customer_ID],Table3[[Gender]:[State]])} -> Male | F12: Port Michaelburgh | G12: Pennsylvania | H12: =IF(OR(Customer_Dim!G12="usa",G12="United States of America"),"USA") -> USA | I12: =VLOOKUP(A12,Customer_Dim!A:H,8,0) -> Bronze
A13: CUST1011 | B13: =PROPER(Table3[[#This Row],[Name]]) -> Brian Lopez | C13: =VLOOKUP(B13,Customer_Dim!B:C,2,0) -> 28 | D13: =IF(C13<30,"Young",IF(C13<=50,"Middle-Aged","Senior")) -> Young | E13: {=_xlfn.XLOOKUP(A13,Table3[Customer_ID],Table3[[Gender]:[State]])} -> Female | F13: East Krista | G13: New York | H13: =IF(OR(Customer_Dim!G13="usa",G13="United States of America"),"USA") -> USA | I13: =VLOOKUP(A13,Customer_Dim!A:H,8,0) -> Gold
A14: CUST1012 | B14: =PROPER(Table3[[#This Row],[Name]]) -> Kenneth Lambert | C14: =VLOOKUP(B14,Customer_Dim!B:C,2,0) -> 55 | D14: =IF(C14<30,"Young",IF(C14<=50,"Middle-Aged","Senior")) -> Senior | E14: {=_xlfn.XLOOKUP(A14,Table3[Customer_ID],Table3[[Gender]:[State]])} -> Female | F14: North Kathryn | G14: Kansas | H14: =IF(OR(Customer_Dim!G14="usa",G14="United States of America"),"USA") -> USA | I14: =VLOOKUP(A14,Customer_Dim!A:H,8,0) -> Platinum
... A19: CUST1017 | B19: =PROPER(Table3[[#This Row],[Name]]) -> Adam Cruz | C19: =VLOOKUP(B19,Customer_Dim!B:C,2,0) -> 60 | D19: =IF(C19<30,"Young",IF(C19<=50,"Middle-Aged","Senior")) -> Senior | E19: {=_xlfn.XLOOKUP(A19,Table3[Customer_ID],Table3[[Gender]:[State]])} -> Female | F19: Brandonville | G19: Georgia | H19: =IF(OR(Customer_Dim!G19="usa",G19="United States of America"),"USA") -> USA | I19: =VLOOKUP(A19,Customer_Dim!A:H,8,0) -> Platinum
A20: CUST1018 | B20: =PROPER(Table3[[#This Row],[Name]]) -> Rhonda Moss | C20: =VLOOKUP(B20,Customer_Dim!B:C,2,0) -> 43 | D20: =IF(C20<30,"Young",IF(C20<=50,"Middle-Aged","Senior")) -> Middle-Aged | E20: {=_xlfn.XLOOKUP(A20,Table3[Customer_ID],Table3[[Gender]:[State]])} -> Male | F20: South William | G20: Kansas | H20: =IF(OR(Customer_Dim!G20="usa",G20="United States of America"),"USA") -> USA | I20: Standard
A21: CUST1019 | B21: =PROPER(Table3[[#This Row],[Name]]) -> Michael Torres | C21: =VLOOKUP(B21,Customer_Dim!B:C,2,0) -> 46 | D21: =IF(C21<30,"Young",IF(C21<=50,"Middle-Aged","Senior")) -> Middle-Aged | E21: {=_xlfn.XLOOKUP(A21,Table3[Customer_ID],Table3[[Gender]:[State]])} -> Female | F21: Gonzalezfort | G21: New Jersey | H21: =IF(OR(Customer_Dim!G21="usa",G21="United States of America"),"USA") -> USA | I21: =VLOOKUP(A21,Customer_Dim!A:H,8,0) -> Platinum
A22: CUST1020 | B22: =PROPER(Table3[[#This Row],[Name]]) -> Bridget Allen | C22: =VLOOKUP(B22,Customer_Dim!B:C,2,0) -> 59 | D22: =IF(C22<30,"Young",IF(C22<=50,"Middle-Aged","Senior")) -> Senior | E22: {=_xlfn.XLOOKUP(A22,Table3[Customer_ID],Table3[[Gender]:[State]])} -> Male | F22: Lake Shaneburgh | G22: Delaware | H22: =IF(OR(Customer_Dim!G22="usa",G22="United States of America"),"USA") -> USA | I22: =VLOOKUP(A22,Customer_Dim!A:H,8,0) -> Silver
A23: CUST1021 | B23: =PROPER(Table3[[#This Row],[Name]]) -> Jeff Martinez | C23: =VLOOKUP(B23,Customer_Dim!B:C,2,0) -> 36 | D23: =IF(C23<30,"Young",IF(C23<=50,"Middle-Aged","Senior")) -> Middle-Aged | E23: {=_xlfn.XLOOKUP(A23,Table3[Customer_ID],Table3[[Gender]:[State]])} -> Female | F23: Smithburgh | G23: Oklahoma | H23: =IF(OR(Customer_Dim!G23="usa",G23="United States of America"),"USA") -> USA | I23: =VLOOKUP(A23,Customer_Dim!A:H,8,0) -> Gold
A24: CUST1022 | B24: =PROPER(Table3[[#This Row],[Name]]) -> Paul Fox | C24: =VLOOKUP(B24,Customer_Dim!B:C,2,0) -> 33 | D24: =IF(C24<30,"Young",IF(C24<=50,"Middle-Aged","Senior")) -> Middle-Aged | E24: {=_xlfn.XLOOKUP(A24,Table3[Customer_ID],Table3[[Gender]:[State]])} -> Female | F24: Michaelton | G24: Hawaii | H24: =IF(OR(Customer_Dim!G24="usa",G24="United States of America"),"USA") -> USA | I24: =VLOOKUP(A24,Customer_Dim!A:H,8,0) -> Silver
A25: CUST1023 | B25: =PROPER(Table3[[#This Row],[Name]]) -> Jonathan Steele | C25: =VLOOKUP(B25,Customer_Dim!B:C,2,0) -> 52 | D25: =IF(C25<30,"Young",IF(C25<=50,"Middle-Aged","Senior")) -> Senior | E25: {=_xlfn.XLOOKUP(A25,Table3[Customer_ID],Table3[[Gender]:[State]])} -> Female | F25: Molinabury | G25: Oregon | H25: =IF(OR(Customer_Dim!G25="usa",G25="United States of America"),"USA") -> USA | I25: =VLOOKUP(A25,Customer_Dim!A:H,8,0) -> Silver
A26: CUST1024 | B26: =PROPER(Table3[[#This Row],[Name]]) -> Heather Collins | C26: =VLOOKUP(B26,Customer_Dim!B:C,2,0) -> 40 | D26: =IF(C26<30,"Young",IF(C26<=50,"Middle-Aged","Senior")) -> Middle-Aged | E26: {=_xlfn.XLOOKUP(A26,Table3[Customer_ID],Table3[[Gender]:[State]])} -> Male | F26: Rogerschester | G26: Idaho | H26: =IF(OR(Customer_Dim!G26="usa",G26="United States of America"),"USA") -> USA | I26: =VLOOKUP(A26,Customer_Dim!A:H,8,0) -> Platinum
A27: CUST1025 | B27: =PROPER(Table3[[#This Row],[Name]]) -> Diana Taylor | C27: =VLOOKUP(B27,Customer_Dim!B:C,2,0) -> 59 | D27: =IF(C27<30,"Young",IF(C27<=50,"Middle-Aged","Senior")) -> Senior | E27: {=_xlfn.XLOOKUP(A27,Table3[Customer_ID],Table3[[Gender]:[State]])} -> Female | F27: Vasqueztown | G27: California | H27: =IF(OR(Customer_Dim!G27="usa",G27="United States of America"),"USA") -> USA | I27: =VLOOKUP(A27,Customer_Dim!A:H,8,0) -> Bronze
A28: CUST1026 | B28: =PROPER(Table3[[#This Row],[Name]]) -> Amber Carlson | C28: =VLOOKUP(B28,Customer_Dim!B:C,2,0) -> 18 | D28: =IF(C28<30,"Young",IF(C28<=50,"Middle-Aged","Senior")) -> Young | E28: {=_xlfn.XLOOKUP(A28,Table3[Customer_ID],Table3[[Gender]:[State]])} -> Female | F28: East Michellemouth | G28: Missouri | H28: =IF(OR(Customer_Dim!G28="usa",G28="United States of America"),"USA") -> USA | I28: =VLOOKUP(A28,Customer_Dim!A:H,8,0) -> Gold
A29: CUST1027 | B29: =PROPER(Table3[[#This Row],[Name]]) -> Leslie Johnson | C29: =VLOOKUP(B29,Customer_Dim!B:C,2,0) -> 31 | D29: =IF(C29<30,"Young",IF(C29<=50,"Middle-Aged","Senior")) -> Middle-Aged | E29: {=_xlfn.XLOOKUP(A29,Table3[Customer_ID],Table3[[Gender]:[State]])} -> Male | F29: Mollyshire | G29: Utah | H29: =IF(OR(Customer_Dim!G29="usa",G29="United States of America"),"USA") -> USA | I29: Standard
A30: CUST1028 | B30: =PROPER(Table3[[#This Row],[Name]]) -> Joshua Ryan | C30: =VLOOKUP(B30,Customer_Dim!B:C,2,0) -> 27 | D30: =IF(C30<30,"Young",IF(C30<=50,"Middle-Aged","Senior")) -> Young | E30: {=_xlfn.XLOOKUP(A30,Table3[Customer_ID],Table3[[Gender]:[State]])} -> Female | F30: New David | G30: New Jersey | H30: =IF(OR(Customer_Dim!G30="usa",G30="United States of America"),"USA") -> USA | I30: =VLOOKUP(A30,Customer_Dim!A:H,8,0) -> Platinum
A31: CUST1029 | B31: =PROPER(Table3[[#This Row],[Name]]) -> David Arnold | C31: =VLOOKUP(B31,Customer_Dim!B:C,2,0) -> 54 | D31: =IF(C31<30,"Young",IF(C31<=50,"Middle-Aged","Senior")) -> Senior | E31: {=_xlfn.XLOOKUP(A31,Table3[Customer_ID],Table3[[Gender]:[State]])} -> Female | F31: East Jennifer | G31: California | H31: =IF(OR(Customer_Dim!G31="usa",G31="United States of America"),"USA") -> USA | I31: =VLOOKUP(A31,Customer_Dim!A:H,8,0) -> Silver
A32: CUST1030 | B32: =PROPER(Table3[[#This Row],[Name]]) -> Jessica Acevedo | C32: =VLOOKUP(B32,Customer_Dim!B:C,2,0) -> 64 | D32: =IF(C32<30,"Young",IF(C32<=50,"Middle-Aged","Senior")) -> Senior | E32: {=_xlfn.XLOOKUP(A32,Table3[Customer_ID],Table3[[Gender]:[State]])} -> Female | F32: Amybury | G32: Pennsylvania | H32: =IF(OR(Customer_Dim!G32="usa",G32="United States of America"),"USA") -> USA | I32: =VLOOKUP(A32,Customer_Dim!A:H,8,0) -> Bronze
A33: CUST1031 | B33: =PROPER(Table3[[#This Row],[Name]]) -> Sarah Vance | C33: =VLOOKUP(B33,Customer_Dim!B:C,2,0) -> 41 | D33: =IF(C33<30,"Young",IF(C33<=50,"Middle-Aged","Senior")) -> Middle-Aged | E33: {=_xlfn.XLOOKUP(A33,Table3[Customer_ID],Table3[[Gender]:[State]])} -> Male | F33: Johnsonville | G33: Oregon | H33: =IF(OR(Customer_Dim!G33="usa",G33="United States of America"),"USA") -> USA | I33: =VLOOKUP(A33,Customer_Dim!A:H,8,0) -> Silver
A34: CUST1032 | B34: =PROPER(Table3[[#This Row],[Name]]) -> Mike Jennings | C34: =VLOOKUP(B34,Customer_Dim!B:C,2,0) -> 48 | D34: =IF(C34<30,"Young",IF(C34<=50,"Middle-Aged","Senior")) -> Middle-Aged | E34: {=_xlfn.XLOOKUP(A34,Table3[Customer_ID],Table3[[Gender]:[State]])} -> Female | F34: Fostermouth | G34: Arizona | H34: =IF(OR(Customer_Dim!G34="usa",G34="United States of America"),"USA") -> USA | I34: =VLOOKUP(A34,Customer_Dim!A:H,8,0) -> Gold
A35: CUST1033 | B35: =PROPER(Table3[[#This Row],[Name]]) -> Robert Jones Dds | C35: =VLOOKUP(B35,Customer_Dim!B:C,2,0) -> 25 | D35: =IF(C35<30,"Young",IF(C35<=50,"Middle-Aged","Senior")) -> Young | E35: {=_xlfn.XLOOKUP(A35,Table3[Customer_ID],Table3[[Gender]:[State]])} -> Male | F35: Tristanton | G35: Oklahoma | H35: =IF(OR(Customer_Dim!G35="usa",G35="United States of America"),"USA") -> USA | I35: =VLOOKUP(A35,Customer_Dim!A:H,8,0) -> Platinum
A36: CUST1034 | B36: =PROPER(Table3[[#This Row],[Name]]) -> Christopher Olson | C36: =VLOOKUP(B36,Customer_Dim!B:C,2,0) -> 27 | D36: =IF(C36<30,"Young",IF(C36<=50,"Middle-Aged","Senior")) -> Young | E36: {=_xlfn.XLOOKUP(A36,Table3[Customer_ID],Table3[[Gender]:[State]])} -> Female | F36: West Richard | G36: Maryland | H36: =IF(OR(Customer_Dim!G36="usa",G36="United States of America"),"USA") -> USA | I36: =VLOOKUP(A36,Customer_Dim!A:H,8,0) -> Platinum
A37: CUST1035 | B37: =PROPER(Table3[[#This Row],[Name]]) -> Rachel Myers | C37: =VLOOKUP(B37,Customer_Dim!B:C,2,0) -> 52 | D37: =IF(C37<30,"Young",IF(C37<=50,"Middle-Aged","Senior")) -> Senior | E37: {=_xlfn.XLOOKUP(A37,Table3[Customer_ID],Table3[[Gender]:[State]])} -> Male | F37: Robertberg | G37: North Dakota | H37: =IF(OR(Customer_Dim!G37="usa",G37="United States of America"),"USA") -> USA | I37: =VLOOKUP(A37,Customer_Dim!A:H,8,0) -> Silver
A38: CUST1036 | B38: =PROPER(Table3[[#This Row],[Name]]) -> Thomas Phillips | C38: =VLOOKUP(B38,Customer_Dim!B:C,2,0) -> 20 | D38: =IF(C38<30,"Young",IF(C38<=50,"Middle-Aged","Senior")) -> Young | E38: {=_xlfn.XLOOKUP(A38,Table3[Customer_ID],Table3[[Gender]:[State]])} -> Female | F38: Luisfurt | G38: Georgia | H38: =IF(OR(Customer_Dim!G38="usa",G38="United States of America"),"USA") -> USA | I38: =VLOOKUP(A38,Customer_Dim!A:H,8,0) -> Gold
A39: CUST1037 | B39: =PROPER(Table3[[#This Row],[Name]]) -> Christopher Carter | C39: =VLOOKUP(B39,Customer_Dim!B:C,2,0) -> 27 | D39: =IF(C39<30,"Young",IF(C39<=50,"Middle-Aged","Senior")) -> Young | E39: {=_xlfn.XLOOKUP(A39,Table3[Customer_ID],Table3[[Gender]:[State]])} -> Female | F39: Brendastad | G39: South Dakota | H39: =IF(OR(Customer_Dim!G39="usa",G39="United States of America"),"USA") -> USA | I39: Standard
A40: CUST1038 | B40: =PROPER(Table3[[#This Row],[Name]]) -> Deanna Simpson | C40: =VLOOKUP(B40,Customer_Dim!B:C,2,0) -> 35 | D40: =IF(C40<30,"Young",IF(C40<=50,"Middle-Aged","Senior")) -> Middle-Aged | E40: {=_xlfn.XLOOKUP(A40,Table3[Customer_ID],Table3[[Gender]:[State]])} -> Female | F40: Brownport | G40: North Dakota | H40: =IF(OR(Customer_Dim!G40="usa",G40="United States of America"),"USA") -> USA | I40: =VLOOKUP(A40,Customer_Dim!A:H,8,0) -> Bronze
A41: CUST1039 | B41: =PROPER(Table3[[#This Row],[Name]]) -> Tonya Reynolds | C41: =VLOOKUP(B41,Customer_Dim!B:C,2,0) -> 55 | D41: =IF(C41<30,"Young",IF(C41<=50,"Middle-Aged","Senior")) -> Senior | E41: {=_xlfn.XLOOKUP(A41,Table3[Customer_ID],Table3[[Gender]:[State]])} -> Female | F41: Darleneton | G41: Michigan | H41: =IF(OR(Customer_Dim!G41="usa",G41="United States of America"),"USA") -> USA | I41: =VLOOKUP(A41,Customer_Dim!A:H,8,0) -> Gold
A42: CUST1040 | B42: =PROPER(Table3[[#This Row],[Name]]) -> Eric Vega | C42: =VLOOKUP(B42,Customer_Dim!B:C,2,0) -> 50 | D42: =IF(C42<30,"Young",IF(C42<=50,"Middle-Aged","Senior")) -> Middle-Aged | E42: {=_xlfn.XLOOKUP(A42,Table3[Customer_ID],Table3[[Gender]:[State]])} -> Male | F42: Williamsonland | G42: Kansas | H42: =IF(OR(Customer_Dim!G42="usa",G42="United States of America"),"USA") -> USA | I42: =VLOOKUP(A42,Customer_Dim!A:H,8,0) -> Gold
A43: CUST1041 | B43: =PROPER(Table3[[#This Row],[Name]]) -> James Gibbs | C43: =VLOOKUP(B43,Customer_Dim!B:C,2,0) -> 21 | D43: =IF(C43<30,"Young",IF(C43<=50,"Middle-Aged","Senior")) -> Young | E43: {=_xlfn.XLOOKUP(A43,Table3[Customer_ID],Table3[[Gender]:[State]])} -> Male | F43: Mooneyshire | G43: Alaska | H43: =IF(OR(Customer_Dim!G43="usa",G43="United States of America"),"USA") -> USA | I43: =VLOOKUP(A43,Customer_Dim!A:H,8,0) -> Platinum
A44: CUST1042 | B44: =PROPER(Table3[[#This Row],[Name]]) -> William Martin | C44: =VLOOKUP(B44,Customer_Dim!B:C,2,0) -> 19 | D44: =IF(C44<30,"Young",IF(C44<=50,"Middle-Aged","Senior")) -> Young | E44: {=_xlfn.XLOOKUP(A44,Table3[Customer_ID],Table3[[Gender]:[State]])} -> Male | F44: Ryanburgh | G44: Connecticut | H44: =IF(OR(Customer_Dim!G44="usa",G44="United States of America"),"USA") -> USA | I44: =VLOOKUP(A44,Customer_Dim!A:H,8,0) -> Platinum
...

Sheet PIVOT_Product & Sales Facts
A3: Sum of Unit_Price | B3: Column Labels
A4: Row Labels | B4: COD | C4: Credit Card | D4: PayPal | E4: Grand Total
A5: Beauty | B5: 50392.66 | C5: 60486.47 | D5: 56349.64 | E5: 167228.77
A6: Clothing | B6: 55223.14 | C6: 54923.93 | D6: 57546.61 | E6: 167693.68
A7: Electronics | B7: 78406.09 | C7: 82187.27 | D7: 90103.46 | E7: 250696.82
A8: Home | B8: 58449.92 | C8: 52400.47 | D8: 70023.63 | E8: 180874.02
A9: Sports | B9: 86302.06 | C9: 81224.51 | D9: 85740.03 | E9: 253266.6
A10: Grand Total | B10: 328773.87 | C10: 331222.65 | D10: 359763.37 | E10: 1019759.9

Sheet Charts

Sheet Sheet5
A3: Row Labels | B3: Sum of Discount | C3: Sum of Unit_Price | D3: Count of Sales_ID
A4: COD | B4: 97.62 | C4: 328773.87 | D4: 656
A5: Credit Card | B5: 96.33 | C5: 331222.65 | D5: 639
A6: PayPal | B6: 100.46 | C6: 359763.37 | D6: 690
A7: Grand Total | B7: 294.41 | C7: 1019759.9 | D7: 1985

Sheet Combine Products & Sales Facts
A1: Sales_ID | B1: Order_Date | C1: Customer_ID | D1: Customer_Name | E1: Product_ID | F1: Product_Category | G1: Store_ID | H1: Quantity | I1: Unit_Price | J1: Discount | K1: Payment_Type | L1: Total_Amount
A2: SALE0 | B2: {=_xlfn.XLOOKUP(A2,Sales_Fact!A2:A1986,Sales_Fact!B2:C1986)} -> 45480 | C2: CUST1409 | D2: =VLOOKUP('Combine Products & Sales Facts'!C2,'Customer Details'!A:B,2,0) -> Sarah Smith | E2: =VLOOKUP(C2,Sales_Fact!C:D,2,0) -> PROD97 | F2: =VLOOKUP(E2,Product_Dim!A:C,3,0) -> Sports | G2: {=_xlfn.XLOOKUP(C2,Sales_Fact!C2:C1986,Sales_Fact!E2:J1986)} -> STORE3 | H2: 1 | I2: 218.04 | J2: 0.09 | K2: Credit Card | L2: 198.4164
A3: SALE1 | B3: {=_xlfn.XLOOKUP(A3,Sales_Fact!A3:A1987,Sales_Fact!B3:C1987)} -> 45285 | C3: CUST1467 | D3: =VLOOKUP('Combine Products & Sales Facts'!C3,'Customer Details'!A:B,2,0) -> Michael Foley | E3: =VLOOKUP(C3,Sales_Fact!C:D,2,0) -> PROD74 | F3: =VLOOKUP(E3,Product_Dim!A:C,3,0) -> Electronics | G3: {=_xlfn.XLOOKUP(C3,Sales_Fact!C3:C1987,Sales_Fact!E3:J1987)} -> STORE17 | H3: 3 | I3: 104.47 | J3: 0.27 | K3: PayPal | L3: 228.7893
A4: SALE2 | B4: {=_xlfn.XLOOKUP(A4,Sales_Fact!A4:A1988,Sales_Fact!B4:C1988)} -> 45446 | C4: CUST1056 | D4: =VLOOKUP('Combine Products & Sales Facts'!C4,'Customer Details'!A:B,2,0) -> Christopher Sutton | E4: =VLOOKUP(C4,Sales_Fact!C:D,2,0) -> PROD49 | F4: =VLOOKUP(E4,Product_Dim!A:C,3,0) -> Beauty | G4: {=_xlfn.XLOOKUP(C4,Sales_Fact!C4:C1988,Sales_Fact!E4:J1988)} -> STORE8 | H4: 4 | I4: 914.05 | J4: 0.25 | K4: Credit Card | L4: 2742.15
A5: SALE3 | B5: {=_xlfn.XLOOKUP(A5,Sales_Fact!A5:A1989,Sales_Fact!B5:C1989)} -> 45259 | C5: CUST1346 | D5: =VLOOKUP('Combine Products & Sales Facts'!C5,'Customer Details'!A:B,2,0) -> John Jordan | E5: =VLOOKUP(C5,Sales_Fact!C:D,2,0) -> PROD76 | F5: =VLOOKUP(E5,Product_Dim!A:C,3,0) -> Electronics | G5: {=_xlfn.XLOOKUP(C5,Sales_Fact!C5:C1989,Sales_Fact!E5:J1989)} -> STORE8 | H5: 1 | I5: 921.51 | J5: 0.16 | K5: COD | L5: 774.0684
A6: SALE4 | B6: {=_xlfn.XLOOKUP(A6,Sales_Fact!A6:A1990,Sales_Fact!B6:C1990)} -> 45297 | C6: CUST1493 | D6: =VLOOKUP('Combine Products & Sales Facts'!C6,'Customer Details'!A:B,2,0) -> Amanda Powell | E6: =VLOOKUP(C6,Sales_Fact!C:D,2,0) -> PROD59 | F6: =VLOOKUP(E6,Product_Dim!A:C,3,0) -> Beauty | G6: {=_xlfn.XLOOKUP(C6,Sales_Fact!C6:C1990,Sales_Fact!E6:J1990)} -> STORE5 | H6: 3 | I6: 745.3 | J6: 0.18 | K6: Credit Card | L6: 1833.438
A7: SALE5 | B7: {=_xlfn.XLOOKUP(A7,Sales_Fact!A7:A1991,Sales_Fact!B7:C1991)} -> 45499 | C7: CUST1116 | D7: =VLOOKUP('Combine Products & Sales Facts'!C7,'Customer Details'!A:B,2,0) -> Anthony Phillips | E7: =VLOOKUP(C7,Sales_Fact!C:D,2,0) -> PROD15 | F7: =VLOOKUP(E7,Product_Dim!A:C,3,0) -> Electronics | G7: {=_xlfn.XLOOKUP(C7,Sales_Fact!C7:C1991,Sales_Fact!E7:J1991)} -> STORE7 | H7: 3 | I7: 147.01 | J7: 0.19 | K7: COD | L7: 357.2343
A8: SALE6 | B8: {=_xlfn.XLOOKUP(A8,Sales_Fact!A8:A1992,Sales_Fact!B8:C1992)} -> 45850 | C8: CUST1016 | D8: =VLOOKUP('Combine Products & Sales Facts'!C8,'Customer Details'!A:B,2,0) -> John Scott | E8: =VLOOKUP(C8,Sales_Fact!C:D,2,0) -> PROD56 | F8: =VLOOKUP(E8,Product_Dim!A:C,3,0) -> Home | G8: {=_xlfn.XLOOKUP(C8,Sales_Fact!C8:C1992,Sales_Fact!E8:J1992)} -> STORE4 | H8: 2 | I8: 785.31 | J8: 0.15 | K8: PayPal | L8: 1335.027
A9: SALE7 | B9: {=_xlfn.XLOOKUP(A9,Sales_Fact!A9:A1993,Sales_Fact!B9:C1993)} -> 45248 | C9: CUST1152 | D9: =VLOOKUP('Combine Products & Sales Facts'!C9,'Customer Details'!A:B,2,0) -> Patrick Roberts | E9: =VLOOKUP(C9,Sales_Fact!C:D,2,0) -> PROD70 | F9: =VLOOKUP(E9,Product_Dim!A:C,3,0) -> Home | G9: {=_xlfn.XLOOKUP(C9,Sales_Fact!C9:C1993,Sales_Fact!E9:J1993)} -> STORE8 | H9: 4 | I9: 342.39 | J9: 0.23 | K9: PayPal | L9: 1054.5612
A10: SALE8 | B10: {=_xlfn.XLOOKUP(A10,Sales_Fact!A10:A1994,Sales_Fact!B10:C1994)} -> 45869 | C10: CUST1464 | D10: =VLOOKUP('Combine Products & Sales Facts'!C10,'Customer Details'!A:B,2,0) -> David Pierce | E10: =VLOOKUP(C10,Sales_Fact!C:D,2,0) -> PROD33 | F10: =VLOOKUP(E10,Product_Dim!A:C,3,0) -> Home | G10: {=_xlfn.XLOOKUP(C10,Sales_Fact!C10:C1994,Sales_Fact!E10:J1994)} -> STORE0 | H10: 2 | I10: 873.17 | J10: 0.23 | K10: PayPal | L10: 1344.6818
A11: SALE9 | B11: {=_xlfn.XLOOKUP(A11,Sales_Fact!A11:A1995,Sales_Fact!B11:C1995)} -> 45335 | C11: CUST1065 | D11: =VLOOKUP('Combine Products & Sales Facts'!C11,'Customer Details'!A:B,2,0) -> Michael Thomas | E11: =VLOOKUP(C11,Sales_Fact!C:D,2,0) -> PROD24 | F11: =VLOOKUP(E11,Product_Dim!A:C,3,0) -> Sports | G11: {=_xlfn.XLOOKUP(C11,Sales_Fact!C11:C1995,Sales_Fact!E11:J1995)} -> STORE14 | H11: 1 | I11: 278.63 | J11: 0.07 | K11: Credit Card | L11: 259.1259
A12: SALE10 | B12: {=_xlfn.XLOOKUP(A12,Sales_Fact!A12:A1996,Sales_Fact!B12:C1996)} -> 45801 | C12: CUST1320 | D12: =VLOOKUP('Combine Products & Sales Facts'!C12,'Customer Details'!A:B,2,0) -> Jessica Gonzalez | E12: =VLOOKUP(C12,Sales_Fact!C:D,2,0) -> PROD39 | F12: =VLOOKUP(E12,Product_Dim!A:C,3,0) -> Electronics | G12: {=_xlfn.XLOOKUP(C12,Sales_Fact!C12:C1996,Sales_Fact!E12:J1996)} -> STORE1 | H12: 4 | I12: 286.92 | J12: 0.17 | K12: Credit Card | L12: 952.5744
A13: SALE11 | B13: {=_xlfn.XLOOKUP(A13,Sales_Fact!A13:A1997,Sales_Fact!B13:C1997)} -> 45528 | C13: CUST1237 | D13: =VLOOKUP('Combine Products & Sales Facts'!C13,'Customer Details'!A:B,2,0) -> Wesley Short | E13: =VLOOKUP(C13,Sales_Fact!C:D,2,0) -> PROD88 | F13: =VLOOKUP(E13,Product_Dim!A:C,3,0) -> Sports | G13: {=_xlfn.XLOOKUP(C13,Sales_Fact!C13:C1997,Sales_Fact!E13:J1997)} -> STORE4 | H13: 4 | I13: 644.58 | J13: 0.01 | K13: Credit Card | L13: 2552.5368
... A1986: SALE1984 | B1986: {=_xlfn.XLOOKUP(A1986,Sales_Fact!A1986:A3970,Sales_Fact!B1986:C3970)} -> 45267 | C1986: CUST1023 | D1986: =VLOOKUP('Combine Products & Sales Facts'!C1986,'Customer Details'!A:B,2,0) -> Jonathan Steele | E1986: =VLOOKUP(C1986,Sales_Fact!C:D,2,0) -> PROD68 | F1986: =VLOOKUP(E1986,Product_Dim!A:C,3,0) -> Home | G1986: {=_xlfn.XLOOKUP(C1986,Sales_Fact!C1986:C3970,Sales_Fact!E1986:J3970)} -> STORE19 | H1986: 3 | I1986: 68.45 | J1986: 0.17 | K1986: PayPal | L1986: 170.4405
K1987: Sum Formula used to CalculateTotyal Amount | L1987: =SUM(L2:L1986) -> 2155273.7
